Exception in Tkinter callback
Traceback (most recent call last):
  File "C:\Program Files (x86)\Python36-32\lib\tkinter\__init__.py", line 1699, in __call__
    return self.func(*args)
TypeError: CancelLogin() takes 0 positional arguments but 1 was given
